  <!-- joints -->
  <joint name="fixed_base_joint" type="fixed">
    <parent link="base_footprint"/>
    <child link="base_link"/>
    <origin xyz="0 0 0" rpy="0 0 0"/>
  </joint>
  <joint name="joint_1" type="revolute">
    <origin xyz="0 0 0.33" rpy="0 0 0"/>
    <parent link="base_link"/>
    <child link="link_1"/>
    <axis xyz="0 0 1"/>
    <limit lower="${-185*deg}" upper="${185*deg}" effort="300" velocity="${123*deg}"/>
  </joint>
  <joint name="joint_2" type="revolute">
    <origin xyz="0.35 0 0.42" rpy="0 0 0"/>
    <parent link="link_1"/>
    <child link="link_2"/>
    <axis xyz="0 1 0"/>
    <limit lower="${-45*deg}" upper="${85*deg}" effort="300" velocity="${115*deg}"/>
  </joint>
  <joint name="joint_3" type="revolute">
    <origin xyz="0 0 1.25" rpy="0 0 0"/>
    <parent link="link_2"/>
    <child link="link_3"/>
    <axis xyz="0 1 0"/>
    <limit lower="${-210*deg}" upper="${(155-90)*deg}" effort="300" velocity="${112*deg}"/>
  </joint>
  <joint name="joint_4" type="revolute">
    <origin xyz="0.96 0 -0.054" rpy="0 0 0"/>
    <parent link="link_3"/>
    <child link="link_4"/>
    <axis xyz="1 0 0"/>
    <limit lower="${-350*deg}" upper="${350*deg}" effort="300" velocity="${179*deg}"/>
  </joint>
  <joint name="joint_5" type="revolute">
    <origin xyz="0.54 0 0" rpy="0 0 0"/>
    <parent link="link_4"/>
    <child link="link_5"/>
    <axis xyz="0 1 0"/>
    <limit lower="${-125*deg}" upper="${125*deg}" effort="300" velocity="${172*deg}"/>
  </joint>
  <joint name="joint_6" type="revolute">
    <origin xyz="0.193 0 0" rpy="0 0 0"/>
    <parent link="link_5"/>
    <child link="link_6"/>
    <axis xyz="1 0 0"/>
    <limit lower="${-350*deg}" upper="${350*deg}" effort="300" velocity="${219*deg}"/>
  </joint>